Workbook

Sheet 首页看板
A1: 每日收货出货与应收回款看板
A2: 登记每天收货/出货，回款按客户或运单号核销；统计页会自动更新。
A4: 本月应收 | C4: 本月已核销 | E4: 当前未收 | G4: 当前毛利润 | I4: 未结算成本
A5: =SUMIFS(每日收货出货登记!$Q:$Q,每日收货出货登记!$A:$A,">="&DATE(YEAR(TODAY()),MONTH(TODAY()),1),每日收货出货登记!$A:$A,"<"&EDATE(DATE(YEAR(TODAY()),MONTH(TODAY()),1),1)) | C5: =SUMIFS(每日收货出货登记!$V:$V,每日收货出货登记!$A:$A,">="&DATE(YEAR(TODAY()),MONTH(TODAY()),1),每日收货出货登记!$A:$A,"<"&EDATE(DATE(YEAR(TODAY()),MONTH(TODAY()),1),1)) | E5: =SUM(每日收货出货登记!$W:$W) | G5: =SUM(每日收货出货登记!$Z:$Z) | I5: =SUMIFS(每日收货出货登记!$Y:$Y,每日收货出货登记!$AA:$AA,"<>已结算PAID")
A8: 最近未收明细 | I8: 使用顺序
A9: 录单日期 | B9: 客户单位 | C9: 运单号 | D9: 应收RMB | E9: 已核销 | F9: 未收 | G9: 货物状态 | I9: 1. 在“每日收货出货登记”新增每天业务。
A10: =IF(每日收货出货登记!W3>0,每日收货出货登记!A3,"") | B10: =IF(每日收货出货登记!W3>0,每日收货出货登记!D3,"") | C10: =IF(每日收货出货登记!W3>0,每日收货出货登记!G3,"") | D10: =IF(每日收货出货登记!W3>0,每日收货出货登记!Q3,"") | E10: =IF(每日收货出货登记!W3>0,每日收货出货登记!V3,"") | F10: =IF(每日收货出货登记!W3>0,每日收货出货登记!W3,"") | G10: =IF(每日收货出货登记!W3>0,每日收货出货登记!S3,"") | I10: 2. 收到款后在“回款核销”登记。
A11: =IF(每日收货出货登记!W4>0,每日收货出货登记!A4,"") | B11: =IF(每日收货出货登记!W4>0,每日收货出货登记!D4,"") | C11: =IF(每日收货出货登记!W4>0,每日收货出货登记!G4,"") | D11: =IF(每日收货出货登记!W4>0,每日收货出货登记!Q4,"") | E11: =IF(每日收货出货登记!W4>0,每日收货出货登记!V4,"") | F11: =IF(每日收货出货登记!W4>0,每日收货出货登记!W4,"") | G11: =IF(每日收货出货登记!W4>0,每日收货出货登记!S4,"") | I11: 3. 有运单号就按运单核销；批量收款可只填客户单位。
A12: =IF(每日收货出货登记!W5>0,每日收货出货登记!A5,"") | B12: =IF(每日收货出货登记!W5>0,每日收货出货登记!D5,"") | C12: =IF(每日收货出货登记!W5>0,每日收货出货登记!G5,"") | D12: =IF(每日收货出货登记!W5>0,每日收货出货登记!Q5,"") | E12: =IF(每日收货出货登记!W5>0,每日收货出货登记!V5,"") | F12: =IF(每日收货出货登记!W5>0,每日收货出货登记!W5,"") | G12: =IF(每日收货出货登记!W5>0,每日收货出货登记!S5,"") | I12: 4. 看“客户应收汇总”和“未核销明细”跟进欠款。
A13: =IF(每日收货出货登记!W6>0,每日收货出货登记!A6,"") | B13: =IF(每日收货出货登记!W6>0,每日收货出货登记!D6,"") | C13: =IF(每日收货出货登记!W6>0,每日收货出货登记!G6,"") | D13: =IF(每日收货出货登记!W6>0,每日收货出货登记!Q6,"") | E13: =IF(每日收货出货登记!W6>0,每日收货出货登记!V6,"") | F13: =IF(每日收货出货登记!W6>0,每日收货出货登记!W6,"") | G13: =IF(每日收货出货登记!W6>0,每日收货出货登记!S6,"")
A14: =IF(每日收货出货登记!W7>0,每日收货出货登记!A7,"") | B14: =IF(每日收货出货登记!W7>0,每日收货出货登记!D7,"") | C14: =IF(每日收货出货登记!W7>0,每日收货出货登记!G7,"") | D14: =IF(每日收货出货登记!W7>0,每日收货出货登记!Q7,"") | E14: =IF(每日收货出货登记!W7>0,每日收货出货登记!V7,"") | F14: =IF(每日收货出货登记!W7>0,每日收货出货登记!W7,"") | G14: =IF(每日收货出货登记!W7>0,每日收货出货登记!S7,"")
A15: =IF(每日收货出货登记!W8>0,每日收货出货登记!A8,"") | B15: =IF(每日收货出货登记!W8>0,每日收货出货登记!D8,"") | C15: =IF(每日收货出货登记!W8>0,每日收货出货登记!G8,"") | D15: =IF(每日收货出货登记!W8>0,每日收货出货登记!Q8,"") | E15: =IF(每日收货出货登记!W8>0,每日收货出货登记!V8,"") | F15: =IF(每日收货出货登记!W8>0,每日收货出货登记!W8,"") | G15: =IF(每日收货出货登记!W8>0,每日收货出货登记!S8,"")
A16: =IF(每日收货出货登记!W9>0,每日收货出货登记!A9,"") | B16: =IF(每日收货出货登记!W9>0,每日收货出货登记!D9,"") | C16: =IF(每日收货出货登记!W9>0,每日收货出货登记!G9,"") | D16: =IF(每日收货出货登记!W9>0,每日收货出货登记!Q9,"") | E16: =IF(每日收货出货登记!W9>0,每日收货出货登记!V9,"") | F16: =IF(每日收货出货登记!W9>0,每日收货出货登记!W9,"") | G16: =IF(每日收货出货登记!W9>0,每日收货出货登记!S9,"")
A17: =IF(每日收货出货登记!W10>0,每日收货出货登记!A10,"") | B17: =IF(每日收货出货登记!W10>0,每日收货出货登记!D10,"") | C17: =IF(每日收货出货登记!W10>0,每日收货出货登记!G10,"") | D17: =IF(每日收货出货登记!W10>0,每日收货出货登记!Q10,"") | E17: =IF(每日收货出货登记!W10>0,每日收货出货登记!V10,"") | F17: =IF(每日收货出货登记!W10>0,每日收货出货登记!W10,"") | G17: =IF(每日收货出货登记!W10>0,每日收货出货登记!S10,"")
A18: =IF(每日收货出货登记!W11>0,每日收货出货登记!A11,"") | B18: =IF(每日收货出货登记!W11>0,每日收货出货登记!D11,"") | C18: =IF(每日收货出货登记!W11>0,每日收货出货登记!G11,"") | D18: =IF(每日收货出货登记!W11>0,每日收货出货登记!Q11,"") | E18: =IF(每日收货出货登记!W11>0,每日收货出货登记!V11,"") | F18: =IF(每日收货出货登记!W11>0,每日收货出货登记!W11,"") | G18: =IF(每日收货出货登记!W11>0,每日收货出货登记!S11,"")
A19: =IF(每日收货出货登记!W12>0,每日收货出货登记!A12,"") | B19: =IF(每日收货出货登记!W12>0,每日收货出货登记!D12,"") | C19: =IF(每日收货出货登记!W12>0,每日收货出货登记!G12,"") | D19: =IF(每日收货出货登记!W12>0,每日收货出货登记!Q12,"") | E19: =IF(每日收货出货登记!W12>0,每日收货出货登记!V12,"") | F19: =IF(每日收货出货登记!W12>0,每日收货出货登记!W12,"") | G19: =IF(每日收货出货登记!W12>0,每日收货出货登记!S12,"")
A20: =IF(每日收货出货登记!W13>0,每日收货出货登记!A13,"") | B20: =IF(每日收货出货登记!W13>0,每日收货出货登记!D13,"") | C20: =IF(每日收货出货登记!W13>0,每日收货出货登记!G13,"") | D20: =IF(每日收货出货登记!W13>0,每日收货出货登记!Q13,"") | E20: =IF(每日收货出货登记!W13>0,每日收货出货登记!V13,"") | F20: =IF(每日收货出货登记!W13>0,每日收货出货登记!W13,"") | G20: =IF(每日收货出货登记!W13>0,每日收货出货登记!S13,"")
A21: =IF(每日收货出货登记!W14>0,每日收货出货登记!A14,"") | B21: =IF(每日收货出货登记!W14>0,每日收货出货登记!D14,"") | C21: =IF(每日收货出货登记!W14>0,每日收货出货登记!G14,"") | D21: =IF(每日收货出货登记!W14>0,每日收货出货登记!Q14,"") | E21: =IF(每日收货出货登记!W14>0,每日收货出货登记!V14,"") | F21: =IF(每日收货出货登记!W14>0,每日收货出货登记!W14,"") | G21: =IF(每日收货出货登记!W14>0,每日收货出货登记!S14,"")
A22: =IF(每日收货出货登记!W15>0,每日收货出货登记!A15,"") | B22: =IF(每日收货出货登记!W15>0,每日收货出货登记!D15,"") | C22: =IF(每日收货出货登记!W15>0,每日收货出货登记!G15,"") | D22: =IF(每日收货出货登记!W15>0,每日收货出货登记!Q15,"") | E22: =IF(每日收货出货登记!W15>0,每日收货出货登记!V15,"") | F22: =IF(每日收货出货登记!W15>0,每日收货出货登记!W15,"") | G22: =IF(每日收货出货登记!W15>0,每日收货出货登记!S15,"")
A23: =IF(每日收货出货登记!W16>0,每日收货出货登记!A16,"") | B23: =IF(每日收货出货登记!W16>0,每日收货出货登记!D16,"") | C23: =IF(每日收货出货登记!W16>0,每日收货出货登记!G16,"") | D23: =IF(每日收货出货登记!W16>0,每日收货出货登记!Q16,"") | E23: =IF(每日收货出货登记!W16>0,每日收货出货登记!V16,"") | F23: =IF(每日收货出货登记!W16>0,每日收货出货登记!W16,"") | G23: =IF(每日收货出货登记!W16>0,每日收货出货登记!S16,"")
A24: =IF(每日收货出货登记!W17>0,每日收货出货登记!A17,"") | B24: =IF(每日收货出货登记!W17>0,每日收货出货登记!D17,"") | C24: =IF(每日收货出货登记!W17>0,每日收货出货登记!G17,"") | D24: =IF(每日收货出货登记!W17>0,每日收货出货登记!Q17,"") | E24: =IF(每日收货出货登记!W17>0,每日收货出货登记!V17,"") | F24: =IF(每日收货出货登记!W17>0,每日收货出货登记!W17,"") | G24: =IF(每日收货出货登记!W17>0,每日收货出货登记!S17,"")

Sheet 每日收货出货登记
A1: 每日收货出货登记
A3: 录单日期 | B3: 业务类型 | C3: 渠道 | D3: 客户单位 | E3: 入仓号/唛头 | F3: 品名 | G3: 运单号 | H3: 始发地 | I3: 目的地 | J3: 运输方式 | K3: 件数 | L3: 实重 | M3: 体积重 | N3: 计费重量 | O3: 收款币种 | P3: 单价 | Q3: =IF(OR(N3="",P3=""),"",N3*P3) | R3: 结算方式 | S3: 货物状态 | T3: 派送日期 | U3: =IF(Q3="","",IF(W3=0,"已付款PAID",IF(V3>0,"部分核销","未付款N/P"))) | V3: =IF(G3="","",SUMIFS(回款核销!$H:$H,回款核销!$C:$C,G3)+SUMIFS(回款核销!$H:$H,回款核销!$B:$B,D3,回款核销!$C:$C,"")) | W3: =IF(Q3="","",MAX(0,Q3-V3)) | X3: 成本单价 | Y3: =IF(OR(N3="",X3=""),"",N3*X3) | Z3: =IF(OR(Q3="",Y3=""),"",Q3-Y3) | AA3: 成本结算状态 | AB3: 备注
Q4: =IF(OR(N4="",P4=""),"",N4*P4) | U4: =IF(Q4="","",IF(W4=0,"已付款PAID",IF(V4>0,"部分核销","未付款N/P"))) | V4: =IF(G4="","",SUMIFS(回款核销!$H:$H,回款核销!$C:$C,G4)+SUMIFS(回款核销!$H:$H,回款核销!$B:$B,D4,回款核销!$C:$C,"")) | W4: =IF(Q4="","",MAX(0,Q4-V4)) | Y4: =IF(OR(N4="",X4=""),"",N4*X4) | Z4: =IF(OR(Q4="",Y4=""),"",Q4-Y4)
Q5: =IF(OR(N5="",P5=""),"",N5*P5) | U5: =IF(Q5="","",IF(W5=0,"已付款PAID",IF(V5>0,"部分核销","未付款N/P"))) | V5: =IF(G5="","",SUMIFS(回款核销!$H:$H,回款核销!$C:$C,G5)+SUMIFS(回款核销!$H:$H,回款核销!$B:$B,D5,回款核销!$C:$C,"")) | W5: =IF(Q5="","",MAX(0,Q5-V5)) | Y5: =IF(OR(N5="",X5=""),"",N5*X5) | Z5: =IF(OR(Q5="",Y5=""),"",Q5-Y5)
Q6: =IF(OR(N6="",P6=""),"",N6*P6) | U6: =IF(Q6="","",IF(W6=0,"已付款PAID",IF(V6>0,"部分核销","未付款N/P"))) | V6: =IF(G6="","",SUMIFS(回款核销!$H:$H,回款核销!$C:$C,G6)+SUMIFS(回款核销!$H:$H,回款核销!$B:$B,D6,回款核销!$C:$C,"")) | W6: =IF(Q6="","",MAX(0,Q6-V6)) | Y6: =IF(OR(N6="",X6=""),"",N6*X6) | Z6: =IF(OR(Q6="",Y6=""),"",Q6-Y6)
Q7: =IF(OR(N7="",P7=""),"",N7*P7) | U7: =IF(Q7="","",IF(W7=0,"已付款PAID",IF(V7>0,"部分核销","未付款N/P"))) | V7: =IF(G7="","",SUMIFS(回款核销!$H:$H,回款核销!$C:$C,G7)+SUMIFS(回款核销!$H:$H,回款核销!$B:$B,D7,回款核销!$C:$C,"")) | W7: =IF(Q7="","",MAX(0,Q7-V7)) | Y7: =IF(OR(N7="",X7=""),"",N7*X7) | Z7: =IF(OR(Q7="",Y7=""),"",Q7-Y7)
Q8: =IF(OR(N8="",P8=""),"",N8*P8) | U8: =IF(Q8="","",IF(W8=0,"已付款PAID",IF(V8>0,"部分核销","未付款N/P"))) | V8: =IF(G8="","",SUMIFS(回款核销!$H:$H,回款核销!$C:$C,G8)+SUMIFS(回款核销!$H:$H,回款核销!$B:$B,D8,回款核销!$C:$C,"")) | W8: =IF(Q8="","",MAX(0,Q8-V8)) | Y8: =IF(OR(N8="",X8=""),"",N8*X8) | Z8: =IF(OR(Q8="",Y8=""),"",Q8-Y8)
Q9: =IF(OR(N9="",P9=""),"",N9*P9) | U9: =IF(Q9="","",IF(W9=0,"已付款PAID",IF(V9>0,"部分核销","未付款N/P"))) | V9: =IF(G9="","",SUMIFS(回款核销!$H:$H,回款核销!$C:$C,G9)+SUMIFS(回款核销!$H:$H,回款核销!$B:$B,D9,回款核销!$C:$C,"")) | W9: =IF(Q9="","",MAX(0,Q9-V9)) | Y9: =IF(OR(N9="",X9=""),"",N9*X9) | Z9: =IF(OR(Q9="",Y9=""),"",Q9-Y9)
Q10: =IF(OR(N10="",P10=""),"",N10*P10) | U10: =IF(Q10="","",IF(W10=0,"已付款PAID",IF(V10>0,"部分核销","未付款N/P"))) | V10: =IF(G10="","",SUMIFS(回款核销!$H:$H,回款核销!$C:$C,G10)+SUMIFS(回款核销!$H:$H,回款核销!$B:$B,D10,回款核销!$C:$C,"")) | W10: =IF(Q10="","",MAX(0,Q10-V10)) | Y10: =IF(OR(N10="",X10=""),"",N10*X10) | Z10: =IF(OR(Q10="",Y10=""),"",Q10-Y10)
Q11: =IF(OR(N11="",P11=""),"",N11*P11) | U11: =IF(Q11="","",IF(W11=0,"已付款PAID",IF(V11>0,"部分核销","未付款N/P"))) | V11: =IF(G11="","",SUMIFS(回款核销!$H:$H,回款核销!$C:$C,G11)+SUMIFS(回款核销!$H:$H,回款核销!$B:$B,D11,回款核销!$C:$C,"")) | W11: =IF(Q11="","",MAX(0,Q11-V11)) | Y11: =IF(OR(N11="",X11=""),"",N11*X11) | Z11: =IF(OR(Q11="",Y11=""),"",Q11-Y11)
Q12: =IF(OR(N12="",P12=""),"",N12*P12) | U12: =IF(Q12="","",IF(W12=0,"已付款PAID",IF(V12>0,"部分核销","未付款N/P"))) | V12: =IF(G12="","",SUMIFS(回款核销!$H:$H,回款核销!$C:$C,G12)+SUMIFS(回款核销!$H:$H,回款核销!$B:$B,D12,回款核销!$C:$C,"")) | W12: =IF(Q12="","",MAX(0,Q12-V12)) | Y12: =IF(OR(N12="",X12=""),"",N12*X12) | Z12: =IF(OR(Q12="",Y12=""),"",Q12-Y12)
Q13: =IF(OR(N13="",P13=""),"",N13*P13) | U13: =IF(Q13="","",IF(W13=0,"已付款PAID",IF(V13>0,"部分核销","未付款N/P"))) | V13: =IF(G13="","",SUMIFS(回款核销!$H:$H,回款核销!$C:$C,G13)+SUMIFS(回款核销!$H:$H,回款核销!$B:$B,D13,回款核销!$C:$C,"")) | W13: =IF(Q13="","",MAX(0,Q13-V13)) | Y13: =IF(OR(N13="",X13=""),"",N13*X13) | Z13: =IF(OR(Q13="",Y13=""),"",Q13-Y13)
Q14: =IF(OR(N14="",P14=""),"",N14*P14) | U14: =IF(Q14="","",IF(W14=0,"已付款PAID",IF(V14>0,"部分核销","未付款N/P"))) | V14: =IF(G14="","",SUMIFS(回款核销!$H:$H,回款核销!$C:$C,G14)+SUMIFS(回款核销!$H:$H,回款核销!$B:$B,D14,回款核销!$C:$C,"")) | W14: =IF(Q14="","",MAX(0,Q14-V14)) | Y14: =IF(OR(N14="",X14=""),"",N14*X14) | Z14: =IF(OR(Q14="",Y14=""),"",Q14-Y14)
Q15: =IF(OR(N15="",P15=""),"",N15*P15) | U15: =IF(Q15="","",IF(W15=0,"已付款PAID",IF(V15>0,"部分核销","未付款N/P"))) | V15: =IF(G15="","",SUMIFS(回款核销!$H:$H,回款核销!$C:$C,G15)+SUMIFS(回款核销!$H:$H,回款核销!$B:$B,D15,回款核销!$C:$C,"")) | W15: =IF(Q15="","",MAX(0,Q15-V15)) | Y15: =IF(OR(N15="",X15=""),"",N15*X15) | Z15: =IF(OR(Q15="",Y15=""),"",Q15-Y15)
... Q1002: =IF(OR(N1002="",P1002=""),"",N1002*P1002) | U1002: =IF(Q1002="","",IF(W1002=0,"已付款PAID",IF(V1002>0,"部分核销","未付款N/P"))) | V1002: =IF(G1002="","",SUMIFS(回款核销!$H:$H,回款核销!$C:$C,G1002)+SUMIFS(回款核销!$H:$H,回款核销!$B:$B,D1002,回款核销!$C:$C,"")) | W1002: =IF(Q1002="","",MAX(0,Q1002-V1002)) | Y1002: =IF(OR(N1002="",X1002=""),"",N1002*X1002) | Z1002: =IF(OR(Q1002="",Y1002=""),"",Q1002-Y1002)

Sheet 回款核销
A1: 回款核销登记
A3: 回款日期 | B3: 客户单位 | C3: 运单号 | D3: 收款账户 | E3: 收款币种 | F3: 回款金额 | G3: 汇率 | H3: =IF(F3="","",F3*IF(G3="",1,G3)) | I3: 核销方式 | J3: 备注
H4: =IF(F4="","",F4*IF(G4="",1,G4))
H5: =IF(F5="","",F5*IF(G5="",1,G5))
H6: =IF(F6="","",F6*IF(G6="",1,G6))
H7: =IF(F7="","",F7*IF(G7="",1,G7))
H8: =IF(F8="","",F8*IF(G8="",1,G8))
H9: =IF(F9="","",F9*IF(G9="",1,G9))
H10: =IF(F10="","",F10*IF(G10="",1,G10))
H11: =IF(F11="","",F11*IF(G11="",1,G11))
H12: =IF(F12="","",F12*IF(G12="",1,G12))
H13: =IF(F13="","",F13*IF(G13="",1,G13))
H14: =IF(F14="","",F14*IF(G14="",1,G14))
H15: =IF(F15="","",F15*IF(G15="",1,G15))
... H1002: =IF(F1002="","",F1002*IF(G1002="",1,G1002))

Sheet 客户应收汇总
A1: 客户应收汇总
A3: =IFERROR(INDEX(基础数据!$B$2:$B$500,ROW(A1)),"") | B3: =IF(A3="","",SUMIFS(每日收货出货登记!$Q:$Q,每日收货出货登记!$D:$D,A3)) | C3: =IF(A3="","",SUMIFS(每日收货出货登记!$V:$V,每日收货出货登记!$D:$D,A3)) | D3: =IF(A3="","",SUMIFS(每日收货出货登记!$W:$W,每日收货出货登记!$D:$D,A3)) | E3: =IF(A3="","",COUNTIFS(每日收货出货登记!$D:$D,A3,每日收货出货登记!$G:$G,"<>")) | F3: =IF(A3="","",COUNTIFS(每日收货出货登记!$D:$D,A3,每日收货出货登记!$W:$W,">0")) | G3: =IF(A3="","",MAXIFS(每日收货出货登记!$A:$A,每日收货出货登记!$D:$D,A3))
A4: =IFERROR(INDEX(基础数据!$B$2:$B$500,ROW(A2)),"") | B4: =IF(A4="","",SUMIFS(每日收货出货登记!$Q:$Q,每日收货出货登记!$D:$D,A4)) | C4: =IF(A4="","",SUMIFS(每日收货出货登记!$V:$V,每日收货出货登记!$D:$D,A4)) | D4: =IF(A4="","",SUMIFS(每日收货出货登记!$W:$W,每日收货出货登记!$D:$D,A4)) | E4: =IF(A4="","",COUNTIFS(每日收货出货登记!$D:$D,A4,每日收货出货登记!$G:$G,"<>")) | F4: =IF(A4="","",COUNTIFS(每日收货出货登记!$D:$D,A4,每日收货出货登记!$W:$W,">0")) | G4: =IF(A4="","",MAXIFS(每日收货出货登记!$A:$A,每日收货出货登记!$D:$D,A4))
A5: =IFERROR(INDEX(基础数据!$B$2:$B$500,ROW(A3)),"") | B5: =IF(A5="","",SUMIFS(每日收货出货登记!$Q:$Q,每日收货出货登记!$D:$D,A5)) | C5: =IF(A5="","",SUMIFS(每日收货出货登记!$V:$V,每日收货出货登记!$D:$D,A5)) | D5: =IF(A5="","",SUMIFS(每日收货出货登记!$W:$W,每日收货出货登记!$D:$D,A5)) | E5: =IF(A5="","",COUNTIFS(每日收货出货登记!$D:$D,A5,每日收货出货登记!$G:$G,"<>")) | F5: =IF(A5="","",COUNTIFS(每日收货出货登记!$D:$D,A5,每日收货出货登记!$W:$W,">0")) | G5: =IF(A5="","",MAXIFS(每日收货出货登记!$A:$A,每日收货出货登记!$D:$D,A5))
A6: =IFERROR(INDEX(基础数据!$B$2:$B$500,ROW(A4)),"") | B6: =IF(A6="","",SUMIFS(每日收货出货登记!$Q:$Q,每日收货出货登记!$D:$D,A6)) | C6: =IF(A6="","",SUMIFS(每日收货出货登记!$V:$V,每日收货出货登记!$D:$D,A6)) | D6: =IF(A6="","",SUMIFS(每日收货出货登记!$W:$W,每日收货出货登记!$D:$D,A6)) | E6: =IF(A6="","",COUNTIFS(每日收货出货登记!$D:$D,A6,每日收货出货登记!$G:$G,"<>")) | F6: =IF(A6="","",COUNTIFS(每日收货出货登记!$D:$D,A6,每日收货出货登记!$W:$W,">0")) | G6: =IF(A6="","",MAXIFS(每日收货出货登记!$A:$A,每日收货出货登记!$D:$D,A6))
A7: =IFERROR(INDEX(基础数据!$B$2:$B$500,ROW(A5)),"") | B7: =IF(A7="","",SUMIFS(每日收货出货登记!$Q:$Q,每日收货出货登记!$D:$D,A7)) | C7: =IF(A7="","",SUMIFS(每日收货出货登记!$V:$V,每日收货出货登记!$D:$D,A7)) | D7: =IF(A7="","",SUMIFS(每日收货出货登记!$W:$W,每日收货出货登记!$D:$D,A7)) | E7: =IF(A7="","",COUNTIFS(每日收货出货登记!$D:$D,A7,每日收货出货登记!$G:$G,"<>")) | F7: =IF(A7="","",COUNTIFS(每日收货出货登记!$D:$D,A7,每日收货出货登记!$W:$W,">0")) | G7: =IF(A7="","",MAXIFS(每日收货出货登记!$A:$A,每日收货出货登记!$D:$D,A7))
A8: =IFERROR(INDEX(基础数据!$B$2:$B$500,ROW(A6)),"") | B8: =IF(A8="","",SUMIFS(每日收货出货登记!$Q:$Q,每日收货出货登记!$D:$D,A8)) | C8: =IF(A8="","",SUMIFS(每日收货出货登记!$V:$V,每日收货出货登记!$D:$D,A8)) | D8: =IF(A8="","",SUMIFS(每日收货出货登记!$W:$W,每日收货出货登记!$D:$D,A8)) | E8: =IF(A8="","",COUNTIFS(每日收货出货登记!$D:$D,A8,每日收货出货登记!$G:$G,"<>")) | F8: =IF(A8="","",COUNTIFS(每日收货出货登记!$D:$D,A8,每日收货出货登记!$W:$W,">0")) | G8: =IF(A8="","",MAXIFS(每日收货出货登记!$A:$A,每日收货出货登记!$D:$D,A8))
A9: =IFERROR(INDEX(基础数据!$B$2:$B$500,ROW(A7)),"") | B9: =IF(A9="","",SUMIFS(每日收货出货登记!$Q:$Q,每日收货出货登记!$D:$D,A9)) | C9: =IF(A9="","",SUMIFS(每日收货出货登记!$V:$V,每日收货出货登记!$D:$D,A9)) | D9: =IF(A9="","",SUMIFS(每日收货出货登记!$W:$W,每日收货出货登记!$D:$D,A9)) | E9: =IF(A9="","",COUNTIFS(每日收货出货登记!$D:$D,A9,每日收货出货登记!$G:$G,"<>")) | F9: =IF(A9="","",COUNTIFS(每日收货出货登记!$D:$D,A9,每日收货出货登记!$W:$W,">0")) | G9: =IF(A9="","",MAXIFS(每日收货出货登记!$A:$A,每日收货出货登记!$D:$D,A9))
A10: =IFERROR(INDEX(基础数据!$B$2:$B$500,ROW(A8)),"") | B10: =IF(A10="","",SUMIFS(每日收货出货登记!$Q:$Q,每日收货出货登记!$D:$D,A10)) | C10: =IF(A10="","",SUMIFS(每日收货出货登记!$V:$V,每日收货出货登记!$D:$D,A10)) | D10: =IF(A10="","",SUMIFS(每日收货出货登记!$W:$W,每日收货出货登记!$D:$D,A10)) | E10: =IF(A10="","",COUNTIFS(每日收货出货登记!$D:$D,A10,每日收货出货登记!$G:$G,"<>")) | F10: =IF(A10="","",COUNTIFS(每日收货出货登记!$D:$D,A10,每日收货出货登记!$W:$W,">0")) | G10: =IF(A10="","",MAXIFS(每日收货出货登记!$A:$A,每日收货出货登记!$D:$D,A10))
A11: =IFERROR(INDEX(基础数据!$B$2:$B$500,ROW(A9)),"") | B11: =IF(A11="","",SUMIFS(每日收货出货登记!$Q:$Q,每日收货出货登记!$D:$D,A11)) | C11: =IF(A11="","",SUMIFS(每日收货出货登记!$V:$V,每日收货出货登记!$D:$D,A11)) | D11: =IF(A11="","",SUMIFS(每日收货出货登记!$W:$W,每日收货出货登记!$D:$D,A11)) | E11: =IF(A11="","",COUNTIFS(每日收货出货登记!$D:$D,A11,每日收货出货登记!$G:$G,"<>")) | F11: =IF(A11="","",COUNTIFS(每日收货出货登记!$D:$D,A11,每日收货出货登记!$W:$W,">0")) | G11: =IF(A11="","",MAXIFS(每日收货出货登记!$A:$A,每日收货出货登记!$D:$D,A11))
A12: =IFERROR(INDEX(基础数据!$B$2:$B$500,ROW(A10)),"") | B12: =IF(A12="","",SUMIFS(每日收货出货登记!$Q:$Q,每日收货出货登记!$D:$D,A12)) | C12: =IF(A12="","",SUMIFS(每日收货出货登记!$V:$V,每日收货出货登记!$D:$D,A12)) | D12: =IF(A12="","",SUMIFS(每日收货出货登记!$W:$W,每日收货出货登记!$D:$D,A12)) | E12: =IF(A12="","",COUNTIFS(每日收货出货登记!$D:$D,A12,每日收货出货登记!$G:$G,"<>")) | F12: =IF(A12="","",COUNTIFS(每日收货出货登记!$D:$D,A12,每日收货出货登记!$W:$W,">0")) | G12: =IF(A12="","",MAXIFS(每日收货出货登记!$A:$A,每日收货出货登记!$D:$D,A12))
A13: =IFERROR(INDEX(基础数据!$B$2:$B$500,ROW(A11)),"") | B13: =IF(A13="","",SUMIFS(每日收货出货登记!$Q:$Q,每日收货出货登记!$D:$D,A13)) | C13: =IF(A13="","",SUMIFS(每日收货出货登记!$V:$V,每日收货出货登记!$D:$D,A13)) | D13: =IF(A13="","",SUMIFS(每日收货出货登记!$W:$W,每日收货出货登记!$D:$D,A13)) | E13: =IF(A13="","",COUNTIFS(每日收货出货登记!$D:$D,A13,每日收货出货登记!$G:$G,"<>")) | F13: =IF(A13="","",COUNTIFS(每日收货出货登记!$D:$D,A13,每日收货出货登记!$W:$W,">0")) | G13: =IF(A13="","",MAXIFS(每日收货出货登记!$A:$A,每日收货出货登记!$D:$D,A13))
A14: =IFERROR(INDEX(基础数据!$B$2:$B$500,ROW(A12)),"") | B14: =IF(A14="","",SUMIFS(每日收货出货登记!$Q:$Q,每日收货出货登记!$D:$D,A14)) | C14: =IF(A14="","",SUMIFS(每日收货出货登记!$V:$V,每日收货出货登记!$D:$D,A14)) | D14: =IF(A14="","",SUMIFS(每日收货出货登记!$W:$W,每日收货出货登记!$D:$D,A14)) | E14: =IF(A14="","",COUNTIFS(每日收货出货登记!$D:$D,A14,每日收货出货登记!$G:$G,"<>")) | F14: =IF(A14="","",COUNTIFS(每日收货出货登记!$D:$D,A14,每日收货出货登记!$W:$W,">0")) | G14: =IF(A14="","",MAXIFS(每日收货出货登记!$A:$A,每日收货出货登记!$D:$D,A14))
... A302: =IFERROR(INDEX(基础数据!$B$2:$B$500,ROW(A300)),"") | B302: =IF(A302="","",SUMIFS(每日收货出货登记!$Q:$Q,每日收货出货登记!$D:$D,A302)) | C302: =IF(A302="","",SUMIFS(每日收货出货登记!$V:$V,每日收货出货登记!$D:$D,A302)) | D302: =IF(A302="","",SUMIFS(每日收货出货登记!$W:$W,每日收货出货登记!$D:$D,A302)) | E302: =IF(A302="","",COUNTIFS(每日收货出货登记!$D:$D,A302,每日收货出货登记!$G:$G,"<>")) | F302: =IF(A302="","",COUNTIFS(每日收货出货登记!$D:$D,A302,每日收货出货登记!$W:$W,">0")) | G302: =IF(A302="","",MAXIFS(每日收货出货登记!$A:$A,每日收货出货登记!$D:$D,A302))

Sheet 未核销明细
A1: 未核销明细
A3: =IF(每日收货出货登记!W3>0,每日收货出货登记!A3,"") | B3: =IF(每日收货出货登记!W3>0,每日收货出货登记!D3,"") | C3: =IF(每日收货出货登记!W3>0,每日收货出货登记!G3,"") | D3: =IF(每日收货出货登记!W3>0,每日收货出货登记!E3,"") | E3: =IF(每日收货出货登记!W3>0,每日收货出货登记!Q3,"") | F3: =IF(每日收货出货登记!W3>0,每日收货出货登记!V3,"") | G3: =IF(每日收货出货登记!W3>0,每日收货出货登记!W3,"") | H3: =IF(每日收货出货登记!W3>0,每日收货出货登记!R3,"") | I3: =IF(每日收货出货登记!W3>0,每日收货出货登记!S3,"") | J3: =IF(每日收货出货登记!W3>0,每日收货出货登记!AB3,"")
A4: =IF(每日收货出货登记!W4>0,每日收货出货登记!A4,"") | B4: =IF(每日收货出货登记!W4>0,每日收货出货登记!D4,"") | C4: =IF(每日收货出货登记!W4>0,每日收货出货登记!G4,"") | D4: =IF(每日收货出货登记!W4>0,每日收货出货登记!E4,"") | E4: =IF(每日收货出货登记!W4>0,每日收货出货登记!Q4,"") | F4: =IF(每日收货出货登记!W4>0,每日收货出货登记!V4,"") | G4: =IF(每日收货出货登记!W4>0,每日收货出货登记!W4,"") | H4: =IF(每日收货出货登记!W4>0,每日收货出货登记!R4,"") | I4: =IF(每日收货出货登记!W4>0,每日收货出货登记!S4,"") | J4: =IF(每日收货出货登记!W4>0,每日收货出货登记!AB4,"")
A5: =IF(每日收货出货登记!W5>0,每日收货出货登记!A5,"") | B5: =IF(每日收货出货登记!W5>0,每日收货出货登记!D5,"") | C5: =IF(每日收货出货登记!W5>0,每日收货出货登记!G5,"") | D5: =IF(每日收货出货登记!W5>0,每日收货出货登记!E5,"") | E5: =IF(每日收货出货登记!W5>0,每日收货出货登记!Q5,"") | F5: =IF(每日收货出货登记!W5>0,每日收货出货登记!V5,"") | G5: =IF(每日收货出货登记!W5>0,每日收货出货登记!W5,"") | H5: =IF(每日收货出货登记!W5>0,每日收货出货登记!R5,"") | I5: =IF(每日收货出货登记!W5>0,每日收货出货登记!S5,"") | J5: =IF(每日收货出货登记!W5>0,每日收货出货登记!AB5,"")
A6: =IF(每日收货出货登记!W6>0,每日收货出货登记!A6,"") | B6: =IF(每日收货出货登记!W6>0,每日收货出货登记!D6,"") | C6: =IF(每日收货出货登记!W6>0,每日收货出货登记!G6,"") | D6: =IF(每日收货出货登记!W6>0,每日收货出货登记!E6,"") | E6: =IF(每日收货出货登记!W6>0,每日收货出货登记!Q6,"") | F6: =IF(每日收货出货登记!W6>0,每日收货出货登记!V6,"") | G6: =IF(每日收货出货登记!W6>0,每日收货出货登记!W6,"") | H6: =IF(每日收货出货登记!W6>0,每日收货出货登记!R6,"") | I6: =IF(每日收货出货登记!W6>0,每日收货出货登记!S6,"") | J6: =IF(每日收货出货登记!W6>0,每日收货出货登记!AB6,"")
A7: =IF(每日收货出货登记!W7>0,每日收货出货登记!A7,"") | B7: =IF(每日收货出货登记!W7>0,每日收货出货登记!D7,"") | C7: =IF(每日收货出货登记!W7>0,每日收货出货登记!G7,"") | D7: =IF(每日收货出货登记!W7>0,每日收货出货登记!E7,"") | E7: =IF(每日收货出货登记!W7>0,每日收货出货登记!Q7,"") | F7: =IF(每日收货出货登记!W7>0,每日收货出货登记!V7,"") | G7: =IF(每日收货出货登记!W7>0,每日收货出货登记!W7,"") | H7: =IF(每日收货出货登记!W7>0,每日收货出货登记!R7,"") | I7: =IF(每日收货出货登记!W7>0,每日收货出货登记!S7,"") | J7: =IF(每日收货出货登记!W7>0,每日收货出货登记!AB7,"")
A8: =IF(每日收货出货登记!W8>0,每日收货出货登记!A8,"") | B8: =IF(每日收货出货登记!W8>0,每日收货出货登记!D8,"") | C8: =IF(每日收货出货登记!W8>0,每日收货出货登记!G8,"") | D8: =IF(每日收货出货登记!W8>0,每日收货出货登记!E8,"") | E8: =IF(每日收货出货登记!W8>0,每日收货出货登记!Q8,"") | F8: =IF(每日收货出货登记!W8>0,每日收货出货登记!V8,"") | G8: =IF(每日收货出货登记!W8>0,每日收货出货登记!W8,"") | H8: =IF(每日收货出货登记!W8>0,每日收货出货登记!R8,"") | I8: =IF(每日收货出货登记!W8>0,每日收货出货登记!S8,"") | J8: =IF(每日收货出货登记!W8>0,每日收货出货登记!AB8,"")
A9: =IF(每日收货出货登记!W9>0,每日收货出货登记!A9,"") | B9: =IF(每日收货出货登记!W9>0,每日收货出货登记!D9,"") | C9: =IF(每日收货出货登记!W9>0,每日收货出货登记!G9,"") | D9: =IF(每日收货出货登记!W9>0,每日收货出货登记!E9,"") | E9: =IF(每日收货出货登记!W9>0,每日收货出货登记!Q9,"") | F9: =IF(每日收货出货登记!W9>0,每日收货出货登记!V9,"") | G9: =IF(每日收货出货登记!W9>0,每日收货出货登记!W9,"") | H9: =IF(每日收货出货登记!W9>0,每日收货出货登记!R9,"") | I9: =IF(每日收货出货登记!W9>0,每日收货出货登记!S9,"") | J9: =IF(每日收货出货登记!W9>0,每日收货出货登记!AB9,"")
A10: =IF(每日收货出货登记!W10>0,每日收货出货登记!A10,"") | B10: =IF(每日收货出货登记!W10>0,每日收货出货登记!D10,"") | C10: =IF(每日收货出货登记!W10>0,每日收货出货登记!G10,"") | D10: =IF(每日收货出货登记!W10>0,每日收货出货登记!E10,"") | E10: =IF(每日收货出货登记!W10>0,每日收货出货登记!Q10,"") | F10: =IF(每日收货出货登记!W10>0,每日收货出货登记!V10,"") | G10: =IF(每日收货出货登记!W10>0,每日收货出货登记!W10,"") | H10: =IF(每日收货出货登记!W10>0,每日收货出货登记!R10,"") | I10: =IF(每日收货出货登记!W10>0,每日收货出货登记!S10,"") | J10: =IF(每日收货出货登记!W10>0,每日收货出货登记!AB10,"")
A11: =IF(每日收货出货登记!W11>0,每日收货出货登记!A11,"") | B11: =IF(每日收货出货登记!W11>0,每日收货出货登记!D11,"") | C11: =IF(每日收货出货登记!W11>0,每日收货出货登记!G11,"") | D11: =IF(每日收货出货登记!W11>0,每日收货出货登记!E11,"") | E11: =IF(每日收货出货登记!W11>0,每日收货出货登记!Q11,"") | F11: =IF(每日收货出货登记!W11>0,每日收货出货登记!V11,"") | G11: =IF(每日收货出货登记!W11>0,每日收货出货登记!W11,"") | H11: =IF(每日收货出货登记!W11>0,每日收货出货登记!R11,"") | I11: =IF(每日收货出货登记!W11>0,每日收货出货登记!S11,"") | J11: =IF(每日收货出货登记!W11>0,每日收货出货登记!AB11,"")
A12: =IF(每日收货出货登记!W12>0,每日收货出货登记!A12,"") | B12: =IF(每日收货出货登记!W12>0,每日收货出货登记!D12,"") | C12: =IF(每日收货出货登记!W12>0,每日收货出货登记!G12,"") | D12: =IF(每日收货出货登记!W12>0,每日收货出货登记!E12,"") | E12: =IF(每日收货出货登记!W12>0,每日收货出货登记!Q12,"") | F12: =IF(每日收货出货登记!W12>0,每日收货出货登记!V12,"") | G12: =IF(每日收货出货登记!W12>0,每日收货出货登记!W12,"") | H12: =IF(每日收货出货登记!W12>0,每日收货出货登记!R12,"") | I12: =IF(每日收货出货登记!W12>0,每日收货出货登记!S12,"") | J12: =IF(每日收货出货登记!W12>0,每日收货出货登记!AB12,"")
A13: =IF(每日收货出货登记!W13>0,每日收货出货登记!A13,"") | B13: =IF(每日收货出货登记!W13>0,每日收货出货登记!D13,"") | C13: =IF(每日收货出货登记!W13>0,每日收货出货登记!G13,"") | D13: =IF(每日收货出货登记!W13>0,每日收货出货登记!E13,"") | E13: =IF(每日收货出货登记!W13>0,每日收货出货登记!Q13,"") | F13: =IF(每日收货出货登记!W13>0,每日收货出货登记!V13,"") | G13: =IF(每日收货出货登记!W13>0,每日收货出货登记!W13,"") | H13: =IF(每日收货出货登记!W13>0,每日收货出货登记!R13,"") | I13: =IF(每日收货出货登记!W13>0,每日收货出货登记!S13,"") | J13: =IF(每日收货出货登记!W13>0,每日收货出货登记!AB13,"")
A14: =IF(每日收货出货登记!W14>0,每日收货出货登记!A14,"") | B14: =IF(每日收货出货登记!W14>0,每日收货出货登记!D14,"") | C14: =IF(每日收货出货登记!W14>0,每日收货出货登记!G14,"") | D14: =IF(每日收货出货登记!W14>0,每日收货出货登记!E14,"") | E14: =IF(每日收货出货登记!W14>0,每日收货出货登记!Q14,"") | F14: =IF(每日收货出货登记!W14>0,每日收货出货登记!V14,"") | G14: =IF(每日收货出货登记!W14>0,每日收货出货登记!W14,"") | H14: =IF(每日收货出货登记!W14>0,每日收货出货登记!R14,"") | I14: =IF(每日收货出货登记!W14>0,每日收货出货登记!S14,"") | J14: =IF(每日收货出货登记!W14>0,每日收货出货登记!AB14,"")
... A502: =IF(每日收货出货登记!W502>0,每日收货出货登记!A502,"") | B502: =IF(每日收货出货登记!W502>0,每日收货出货登记!D502,"") | C502: =IF(每日收货出货登记!W502>0,每日收货出货登记!G502,"") | D502: =IF(每日收货出货登记!W502>0,每日收货出货登记!E502,"") | E502: =IF(每日收货出货登记!W502>0,每日收货出货登记!Q502,"") | F502: =IF(每日收货出货登记!W502>0,每日收货出货登记!V502,"") | G502: =IF(每日收货出货登记!W502>0,每日收货出货登记!W502,"") | H502: =IF(每日收货出货登记!W502>0,每日收货出货登记!R502,"") | I502: =IF(每日收货出货登记!W502>0,每日收货出货登记!S502,"") | J502: =IF(每日收货出货登记!W502>0,每日收货出货登记!AB502,"")

Sheet 客户资料
A1: 客户资料
A3: 唛头 | B3: 发货人 | C3: 发货人电话 | D3: 发货人地址 | E3: 收货人 | F3: 收货人电话 | G3: 收货人地址 | H3: 价格/备注
A4: HASAN1230 | B4: 钟总 | E4: HASAN | F4: 971566536822 | G4: shop no 1 beside heavy signs warehouse behind madina market near mumtaz market and macro on jnp signal street no 2 industrial area no 6 sharjah uae
A5: SS | E5: 邵舒 | F5: 0585252988 | G5: 龙城一期
B6: 袁江江 | C6: 13575934971 | H6: 卖价 60rmb/kg（含义乌进仓+1rmb/kg），返1rmb/kg
B7: OPPO郭玉婷
A8: RJS | B8: CROWN042269449/0551078621
A9: VICKY | E9: Sanaa ElAjjouri | F9: 00971508867417 | G9: Umm alquwain Al salamah3

Sheet 基础数据
A1: 渠道 | B1: 客户单位 | C1: 货物唛头 | D1: 始发地 | E1: 目的地 | F1: 结算方式 | G1: 货物状态 | H1: 运输方式 | I1: 付款状态 | J1: 成本结算状态 | K1: 币种 | L1: 业务类型 | M1: 核销方式
A2: 天龙 | B2: WHD | C2: WHD | D2: 广州GZ | E2: 迪拜DXB | F2: 到付票结DDP | G2: 新货入仓 | H2: 空运双清AIR | I2: 未付款N/P | J2: 未结算N/P | K2: RMB | L2: 收货 | M2: 按运单核销
A3: 迅捷 | B3: CYJ | C3: CYJ | D3: 深圳SZ | E3: 利雅得RUH | F3: 到付周结DWP | G3: 转运中 | H3: 普通空运AIR | I3: 部分核销 | J3: 已结算PAID | K3: AED | L3: 出货 | M3: 按客户预收/批量核销
A4: 三梅 | B4: SEZAR | C4: SEZAR | D4: 义乌YW | E4: 吉达JED | F4: 到付月结DMP | G4: 到达目的地 | H4: 海运双清SEA | I4: 已付款PAID | J4: 部分结算 | K4: USD | L4: 退件 | M4: 退款/冲销
A5: 方显 | B5: HASAN | C5: HASAN1230 | D5: 香港HK | E5: 阿联酋ARE | F5: 预付票结PP | G5: 待清关 | H5: 空空联运AIRAIR | I5: 坏账/无需收款 | J5: 无需结算 | K5: SAR | L5: 费用调整 | M5: 其他
A6: 三羊 | B6: YF一帆 | C6: SF-N2 | D6: 东莞DG | E6: 沙特KSA | F6: 预付周结PW | G6: 派送中 | H6: 海空联运SEAAIR
A7: 一腾 | B7: SF-SARFARAZ | C7: SFF | D7: 中国CN | E7: 伊拉克EBL | F7: 预付月结PM | G7: 完成派送 | H7: 电商海派AE
A8: 众米纳 | B8: MOHAMMAD K | C8: CYJF | D8: 迪拜DXB | E8: 基加利KGL | G8: 今天航班 | H8: 电商海派KSA
A9: 赛时 | B9: lzy李先生 | C9: AL-MOHA | E9: 阿曼OMN | G9: 明天航班 | H9: 电商空派AE
A10: 黄腾DHL | B10: FAIZ | C10: lzy李先生 | E10: 广州CAN | G10: 航班待更新 | H10: 电商空派KSA
A11: 阳光货运 | B11: MVW | C11: FAIZ | E11: 深圳SZX | G11: NEW SHIPMENT | H11: DHL快递
A12: 极航 | B12: 树客国际SK | C12: MVW | G12: IN TRANSIT | H12: 沙特自提
A13: 易通天下 | B13: ZNY | C13: SK072 | G13: ARRIVAL
A14: 义特 | B14: ana赵娜 | C14: SK073 | G14: WAIT FOR CLEARANCE
A15: 海秦HQ | B15: jack116 | C15: 0130663-LZY-B | G15: OUT FOR DELIVERY
A16: UNIVERSAL FREIGHT | B16: ASA-KHALID | C16: SDGYL-MZONE 单独报关 | G16: DELIVERY COMPLETED
B17: SS | C17: 0130668ANAF | G17: TODAY FLIGHT
B18: JACK116 | C18: 0130666JACK116 | G18: TOMORROW FLIGHT
B19: EMIL | C19: 0130667ANA | G19: WAIT FOR FLIGHT UPDATE
B20: REZO-OPPO | C20: 0130669CYJK | G20: 今天派送
B21: 众米纳国际科技 | C21: 0130665CYJF
B22: 袁江江 | C22: 0130682-LZY-A
B23: 义乌博越 | C23: 0130722-CYJ
B24: SAWSAN | C24: SDGYL-251229BY-LYZ/LZY0688
B25: BIGSKY | C25: SDGYL-YF
B26: QA | C26: SDGYL-251229BY-LZY/0694 牌
B27: 何志荣kgl | C27: 111775/MVW
B28: 夏天 | C28: 0130670ASA
B29: 海思托普hstp | C29: 0130680-SS
B30: 海秦HQ | C30: JACK116
B31: 郑总-郑旭生 | C31: 0130761/CYJ
B32: 王智超wzc | C32: 0130764/CYJ
... B84: SMK-Akber | C84: MZONE 0015527
B85: 新创SYNTRANX-GZ | C85: 111870
B86: Foo Maw Twan-OZH | C86: GZSDGYL-HQ-036
B87: SerinLife-ALI | C87: GZSDGYL-HQ-037
B88: SMART VILLAGE-TINA | C88: GZSDGYL-HQ-037-1
B89: 上海中外运 | C89: DQ
B90: JACK-WJ | C90: XCXC-YGMD002
B91: 洋洋YY | C91: XCXC-YGMD003
...
